Workbook

Sheet Requirement Register
A1: ID | B1: Kapitel | C1: Kapitelrubrik | D1: Sektion | E1: Sektionsrubrik | F1: Normativ term | G1: Kravtext
A2: MI-01-001 | B2: 1 | C2: Mobile Intelligence som systemdomän i Omnira | D2: 1.3 | E2: Mobilappen är inte hela domänen | F2: FÅR INTE | G2: Mobile Intelligence SKA definieras som en systemdomän och FÅR INTE reduceras till Omniras mobilapp.
A3: MI-01-002 | B3: 1 | C3: Mobile Intelligence som systemdomän i Omnira | D3: 1.3 | E3: Mobilappen är inte hela domänen | F3: FÅR INTE | G3: Mobilappen SKA vara en kontroll- och interaktionsyta för domänen, men den FÅR INTE vara enda sanningskälla för workflows, authority, approvals eller projektstatus.
A4: MI-01-003 | B4: 1 | C4: Mobile Intelligence som systemdomän i Omnira | D4: 1.4 | E4: Mobilen som fullvärdig Omnira-node | F4: SKA | G4: Mobilen SKA behandlas som en betrodd eller obetrodd Omnira-node beroende på verifierad device identity och aktiv trust-status.
A5: MI-01-004 | B5: 1 | C5: Mobile Intelligence som systemdomän i Omnira | D5: 1.4 | E5: Mobilen som fullvärdig Omnira-node | F5: SKA | G5: En betrodd mobilnod KAN ha flera roller samtidigt, men varje roll och capability SKA vara explicit definierad.
A6: MI-01-005 | B6: 1 | C6: Mobile Intelligence som systemdomän i Omnira | D6: 1.4 | E6: Mobilen som fullvärdig Omnira-node | F6: FÅR INTE | G6: Att en mobil är betrodd FÅR INTE automatiskt ge den full administration, tillgång till alla credentials eller rätt att exekvera alla workflows.
A7: MI-01-006 | B7: 1 | C7: Mobile Intelligence som systemdomän i Omnira | D7: 1.5 | E7: Atlas roll i mobilarkitekturen | F7: SKA | G7: Atlas SKA vara det centrala koordinations- och beslutsstödet för Mobile Intelligence.
A8: MI-01-007 | B8: 1 | C8: Mobile Intelligence som systemdomän i Omnira | D8: 1.5 | E8: Atlas roll i mobilarkitekturen | F8: FÅR INTE | G8: Atlas FÅR INTE behandlas som en global root-behörighet som kan kringgå scope, authority, project isolation eller credential isolation.
A9: MI-01-008 | B9: 1 | C9: Mobile Intelligence som systemdomän i Omnira | D9: 1.5 | E9: Atlas roll i mobilarkitekturen | F9: FÅR INTE | G9: Atlas SKA kunna rekommendera en handling som ligger utanför nuvarande mandat, men FÅR INTE exekvera den innan nödvändigt godkännande finns.
A10: MI-01-009 | B10: 1 | C10: Mobile Intelligence som systemdomän i Omnira | D10: 1.6 | E10: Projektagenter och externa identiteter | F10: SKA | G10: Extern projektidentitet SKA hållas åtskild från intern exekveringsidentitet.
A11: MI-01-010 | B11: 1 | C11: Mobile Intelligence som systemdomän i Omnira | D11: 1.6 | E11: Projektagenter och externa identiteter | F11: FÅR INTE | G11: En projektagent FÅR INTE få tillgång till andra projekt enbart för att Atlas har en global överblick.
A12: MI-01-011 | B12: 1 | C12: Mobile Intelligence som systemdomän i Omnira | D12: 1.6 | E12: Projektagenter och externa identiteter | F12: FÅR INTE | G12: Information om Omniras interna arkitektur FÅR INTE blandas in i projektkommunikation om det inte uttryckligen ingår i projektets godkända externa koncept.
A13: MI-01-012 | B13: 1 | C13: Mobile Intelligence som systemdomän i Omnira | D13: 1.7 | E13: Control surface och execution surface | F13: SKA | G13: Control surface och execution surface SKA behandlas som separata arkitekturdimensioner.
... A507: MI-05-114 | B507: 5 | C507: Authority-modellen L0–L6 | D507: 5.40 | E507: Authority och irreversibilitet | F507: SKA | G507: Irreversibilitet SKA vara en separat riskdimension i authoritybedömningen.
A508: MI-05-115 | B508: 5 | C508: Authority-modellen L0–L6 | D508: 5.40 | E508: Authority och irreversibilitet | G508: En capability kan ha L5 för normala handlingar men L3 för irreversibla undantag.
A509: MI-05-116 | B509: 5 | C509: Authority-modellen L0–L6 | D509: 5.40 | E509: Authority och irreversibilitet | F509: FÅR INTE | G509: L6 FÅR INTE automatiskt omfatta personligt bindande eller förbjudna handlingar.
A510: MI-05-117 | B510: 5 | C510: Authority-modellen L0–L6 | D510: 5.41 | E510: Authority och incidentrespons | F510: SKA | G510: Emergency authority SKA begränsas till fördefinierade riskreducerande handlingar.
A511: MI-05-118 | B511: 5 | C511: Authority-modellen L0–L6 | D511: 5.41 | E511: Authority och incidentrespons | F511: SKA | G511: Automatisk incidentåtgärd SKA meddelas omedelbart.
A512: MI-05-119 | B512: 5 | C512: Authority-modellen L0–L6 | D512: 5.41 | E512: Authority och incidentrespons | F512: FÅR INTE | G512: Emergency authority FÅR INTE användas för permanent privilege expansion.
A513: MI-05-120 | B513: 5 | C513: Authority-modellen L0–L6 | D513: 5.42 | E513: Authority och nödstopp | F513: SKA | G513: Emergency stop SKA omedelbart sänka authority för berörda scopes.
A514: MI-05-121 | B514: 5 | C514: Authority-modellen L0–L6 | D514: 5.42 | E514: Authority och nödstopp | F514: SKA | G514: Nödstopp SKA bevara konfiguration och data om inte separat radering beslutas.
A515: MI-05-122 | B515: 5 | C515: Authority-modellen L0–L6 | D515: 5.42 | E515: Authority och nödstopp | F515: SKA | G515: Återstart SKA återaktivera authority stegvis, inte implicit allt på en gång.
A516: MI-05-123 | B516: 5 | C516: Authority-modellen L0–L6 | D516: 5.43 | E516: Authority och flera agenter | F516: SKA | G516: Delegerad authority SKA vara mindre än eller lika med uppdragsgivarens effective authority.
A517: MI-05-124 | B517: 5 | C517: Authority-modellen L0–L6 | D517: 5.43 | E517: Authority och flera agenter | F517: FÅR INTE | G517: En agent FÅR INTE vidaredelegera authority om detta inte är explicit tillåtet.
A518: MI-05-125 | B518: 5 | C518: Authority-modellen L0–L6 | D518: 5.43 | E518: Authority och flera agenter | F518: SKA | G518: Agentbyte SKA utlösa ny kontroll av authority och dataåtkomst.
A519: MI-05-126 | B519: 5 | C519: Authority-modellen L0–L6 | D519: 5.44 | E519: Authority i organisationer | F519: SKA | G519: Authority governance SKA kunna separeras mellan flera organisatoriska roller.
A520: MI-05-127 | B520: 5 | C520: Authority-modellen L0–L6 | D520: 5.44 | E520: Authority i organisationer | F520: FÅR INTE | G520: Vanlig administratör FÅR INTE automatiskt ändra högsta authoritypolicy.
... A2969: MI-17-031 | B2969: 17 | C2969: Plats, geofencing och fysisk kontext | D2969: 17.10 | E2969: Privat plats | F2969: FÅR INTE | G2969: Projektagent FÅR INTE få personlig plats enbart för att projektet använder mobilen.
A2970: MI-17-032 | B2970: 17 | C2970: Plats, geofencing och fysisk kontext | D2970: 17.10 | E2970: Privat plats | G2970: Projekt får endast få den minsta härledda signal som behövs, exempelvis “användaren är inte tillgänglig för approval just nu”.
A2971: MI-17-033 | B2971: 17 | C2971: Plats, geofencing och fysisk kontext | D2971: 17.10 | E2971: Privat plats | F2971: FÅR INTE | G2971: Privat plats FÅR INTE automatiskt bli globalt långtidsminne.
A2972: MI-17-034 | B2972: 17 | C2972: Plats, geofencing och fysisk kontext | D2972: 17.11 | E2972: Projektplats | F2972: SKA | G2972: Projektplats SKA ha explicit project identity och owner.
A2973: MI-17-035 | B2973: 17 | C2973: Plats, geofencing och fysisk kontext | D2973: 17.11 | E2973: Projektplats | F2973: FÅR INTE | G2973: Projektplats FÅR INTE automatiskt ge projektet användarens personliga rörelsehistorik.
A2974: MI-17-036 | B2974: 17 | C2974: Plats, geofencing och fysisk kontext | D2974: 17.11 | E2974: Projektplats | F2974: SKA | G2974: När personlig plats jämförs mot projektplats SKA endast nödvändig trigger eller relation exponeras till projektet.
A2975: MI-17-037 | B2975: 17 | C2975: Plats, geofencing och fysisk kontext | D2975: 17.12 | E2975: Känsliga platser | F2975: SKA | G2975: Känsliga platser SKA få förhöjd privacyklass.
A2976: MI-17-038 | B2976: 17 | C2976: Plats, geofencing och fysisk kontext | D2976: 17.12 | E2976: Känsliga platser | F2976: FÅR INTE | G2976: Känslig plats FÅR INTE visas i global briefing när en neutral status räcker.
A2977: MI-17-039 | B2977: 17 | C2977: Plats, geofencing och fysisk kontext | D2977: 17.12 | E2977: Känsliga platser | F2977: FÅR INTE | G2977: Känslig plats FÅR INTE delas med projekt eller provider utan konkret behov och explicit scope.
A2978: MI-17-040 | B2978: 17 | C2978: Plats, geofencing och fysisk kontext | D2978: 17.12 | E2978: Känsliga platser | F2978: SKA | G2978: Atlas SKA kunna maskera platsnamn som “privat ärende” eller “otillgänglig” i sekundära vyer.
A2979: MI-17-041 | B2979: 17 | C2979: Plats, geofencing och fysisk kontext | D2979: 17.13 | E2979: Hemmet | F2979: SKA | G2979: Hemmet SKA representeras genom säker platsidentitet eller geofence där exakt adress inte behöver exponeras.
A2980: MI-17-042 | B2980: 17 | C2980: Plats, geofencing och fysisk kontext | D2980: 17.13 | E2980: Hemmet | F2980: FÅR INTE | G2980: Projektagent FÅR INTE få hemadress eller hemkoordinater utan explicit behov.
A2981: MI-17-043 | B2981: 17 | C2981: Plats, geofencing och fysisk kontext | D2981: 17.13 | E2981: Hemmet | F2981: FÅR | G2981: Hemstatus FÅR uttryckas som boolesk signal, exempelvis at_home, när detta räcker.
...

Sheet Per kapitel
A1: Kapitel | B1: Kapitelrubrik | C1: Antal krav | D1: Första ID | E1: Sista ID | F1: SKA | G1: FÅR INTE | H1: BÖR | I1: FÅR | J1: KAN | K1: Utan term
A2: 1 | B2: Mobile Intelligence som systemdomän i Omnira | C2: =COUNTIF('Requirement Register'!$B$2:$B$8921,A2) -> 69 | D2: MI-01-001 | E2: MI-01-069 | F2: =COUNTIFS('Requirement Register'!$B$2:$B$8921,$A2,'Requirement Register'!$F$2:$F$8921,"SKA") -> 37 | G2: =COUNTIFS('Requirement Register'!$B$2:$B$8921,$A2,'Requirement Register'!$F$2:$F$8921,"FÅR INTE") -> 31 | H2: =COUNTIFS('Requirement Register'!$B$2:$B$8921,$A2,'Requirement Register'!$F$2:$F$8921,"BÖR") -> 1 | I2: =COUNTIFS('Requirement Register'!$B$2:$B$8921,$A2,'Requirement Register'!$F$2:$F$8921,"FÅR") -> 0 | J2: =COUNTIFS('Requirement Register'!$B$2:$B$8921,$A2,'Requirement Register'!$F$2:$F$8921,"KAN") -> 0 | K2: =COUNTIFS('Requirement Register'!$B$2:$B$8921,$A2,'Requirement Register'!$F$2:$F$8921,"") -> 0
A3: 2 | B3: Vision, produktomfattning och utvecklingsväg | C3: =COUNTIF('Requirement Register'!$B$2:$B$8921,A3) -> 67 | D3: MI-02-001 | E3: MI-02-067 | F3: =COUNTIFS('Requirement Register'!$B$2:$B$8921,$A3,'Requirement Register'!$F$2:$F$8921,"SKA") -> 41 | G3: =COUNTIFS('Requirement Register'!$B$2:$B$8921,$A3,'Requirement Register'!$F$2:$F$8921,"FÅR INTE") -> 22 | H3: =COUNTIFS('Requirement Register'!$B$2:$B$8921,$A3,'Requirement Register'!$F$2:$F$8921,"BÖR") -> 2 | I3: =COUNTIFS('Requirement Register'!$B$2:$B$8921,$A3,'Requirement Register'!$F$2:$F$8921,"FÅR") -> 1 | J3: =COUNTIFS('Requirement Register'!$B$2:$B$8921,$A3,'Requirement Register'!$F$2:$F$8921,"KAN") -> 1 | K3: =COUNTIFS('Requirement Register'!$B$2:$B$8921,$A3,'Requirement Register'!$F$2:$F$8921,"") -> 0
A4: 3 | B4: Systemaktörer, roller och tillitsrelationer | C4: =COUNTIF('Requirement Register'!$B$2:$B$8921,A4) -> 115 | D4: MI-03-001 | E4: MI-03-115 | F4: =COUNTIFS('Requirement Register'!$B$2:$B$8921,$A4,'Requirement Register'!$F$2:$F$8921,"SKA") -> 70 | G4: =COUNTIFS('Requirement Register'!$B$2:$B$8921,$A4,'Requirement Register'!$F$2:$F$8921,"FÅR INTE") -> 41 | H4: =COUNTIFS('Requirement Register'!$B$2:$B$8921,$A4,'Requirement Register'!$F$2:$F$8921,"BÖR") -> 2 | I4: =COUNTIFS('Requirement Register'!$B$2:$B$8921,$A4,'Requirement Register'!$F$2:$F$8921,"FÅR") -> 1 | J4: =COUNTIFS('Requirement Register'!$B$2:$B$8921,$A4,'Requirement Register'!$F$2:$F$8921,"KAN") -> 1 | K4: =COUNTIFS('Requirement Register'!$B$2:$B$8921,$A4,'Requirement Register'!$F$2:$F$8921,"") -> 0
A5: 4 | B5: Kärnprinciper, invariants och absoluta förbud | C5: =COUNTIF('Requirement Register'!$B$2:$B$8921,A5) -> 141 | D5: MI-04-001 | E5: MI-04-141 | F5: =COUNTIFS('Requirement Register'!$B$2:$B$8921,$A5,'Requirement Register'!$F$2:$F$8921,"SKA") -> 75 | G5: =COUNTIFS('Requirement Register'!$B$2:$B$8921,$A5,'Requirement Register'!$F$2:$F$8921,"FÅR INTE") -> 59 | H5: =COUNTIFS('Requirement Register'!$B$2:$B$8921,$A5,'Requirement Register'!$F$2:$F$8921,"BÖR") -> 5 | I5: =COUNTIFS('Requirement Register'!$B$2:$B$8921,$A5,'Requirement Register'!$F$2:$F$8921,"FÅR") -> 2 | J5: =COUNTIFS('Requirement Register'!$B$2:$B$8921,$A5,'Requirement Register'!$F$2:$F$8921,"KAN") -> 0 | K5: =COUNTIFS('Requirement Register'!$B$2:$B$8921,$A5,'Requirement Register'!$F$2:$F$8921,"") -> 0
A6: 5 | B6: Authority-modellen L0–L6 | C6: =COUNTIF('Requirement Register'!$B$2:$B$8921,A6) -> 144 | D6: MI-05-001 | E6: MI-05-144 | F6: =COUNTIFS('Requirement Register'!$B$2:$B$8921,$A6,'Requirement Register'!$F$2:$F$8921,"SKA") -> 90 | G6: =COUNTIFS('Requirement Register'!$B$2:$B$8921,$A6,'Requirement Register'!$F$2:$F$8921,"FÅR INTE") -> 46 | H6: =COUNTIFS('Requirement Register'!$B$2:$B$8921,$A6,'Requirement Register'!$F$2:$F$8921,"BÖR") -> 2 | I6: =COUNTIFS('Requirement Register'!$B$2:$B$8921,$A6,'Requirement Register'!$F$2:$F$8921,"FÅR") -> 3 | J6: =COUNTIFS('Requirement Register'!$B$2:$B$8921,$A6,'Requirement Register'!$F$2:$F$8921,"KAN") -> 2 | K6: =COUNTIFS('Requirement Register'!$B$2:$B$8921,$A6,'Requirement Register'!$F$2:$F$8921,"") -> 1
A7: 6 | B7: Scope-arkitektur och capability grants | C7: =COUNTIF('Requirement Register'!$B$2:$B$8921,A7) -> 181 | D7: MI-06-001 | E7: MI-06-181 | F7: =COUNTIFS('Requirement Register'!$B$2:$B$8921,$A7,'Requirement Register'!$F$2:$F$8921,"SKA") -> 122 | G7: =COUNTIFS('Requirement Register'!$B$2:$B$8921,$A7,'Requirement Register'!$F$2:$F$8921,"FÅR INTE") -> 55 | H7: =COUNTIFS('Requirement Register'!$B$2:$B$8921,$A7,'Requirement Register'!$F$2:$F$8921,"BÖR") -> 3 | I7: =COUNTIFS('Requirement Register'!$B$2:$B$8921,$A7,'Requirement Register'!$F$2:$F$8921,"FÅR") -> 1 | J7: =COUNTIFS('Requirement Register'!$B$2:$B$8921,$A7,'Requirement Register'!$F$2:$F$8921,"KAN") -> 0 | K7: =COUNTIFS('Requirement Register'!$B$2:$B$8921,$A7,'Requirement Register'!$F$2:$F$8921,"") -> 0
A8: 7 | B8: Approval-arkitektur och mandatets livscykel | C8: =COUNTIF('Requirement Register'!$B$2:$B$8921,A8) -> 164 | D8: MI-07-001 | E8: MI-07-164 | F8: =COUNTIFS('Requirement Register'!$B$2:$B$8921,$A8,'Requirement Register'!$F$2:$F$8921,"SKA") -> 100 | G8: =COUNTIFS('Requirement Register'!$B$2:$B$8921,$A8,'Requirement Register'!$F$2:$F$8921,"FÅR INTE") -> 53 | H8: =COUNTIFS('Requirement Register'!$B$2:$B$8921,$A8,'Requirement Register'!$F$2:$F$8921,"BÖR") -> 4 | I8: =COUNTIFS('Requirement Register'!$B$2:$B$8921,$A8,'Requirement Register'!$F$2:$F$8921,"FÅR") -> 7 | J8: =COUNTIFS('Requirement Register'!$B$2:$B$8921,$A8,'Requirement Register'!$F$2:$F$8921,"KAN") -> 0 | K8: =COUNTIFS('Requirement Register'!$B$2:$B$8921,$A8,'Requirement Register'!$F$2:$F$8921,"") -> 0
A9: 8 | B9: Projektisolering, tenantgränser och Atlas globala vy | C9: =COUNTIF('Requirement Register'!$B$2:$B$8921,A9) -> 190 | D9: MI-08-001 | E9: MI-08-190 | F9: =COUNTIFS('Requirement Register'!$B$2:$B$8921,$A9,'Requirement Register'!$F$2:$F$8921,"SKA") -> 126 | G9: =COUNTIFS('Requirement Register'!$B$2:$B$8921,$A9,'Requirement Register'!$F$2:$F$8921,"FÅR INTE") -> 57 | H9: =COUNTIFS('Requirement Register'!$B$2:$B$8921,$A9,'Requirement Register'!$F$2:$F$8921,"BÖR") -> 0 | I9: =COUNTIFS('Requirement Register'!$B$2:$B$8921,$A9,'Requirement Register'!$F$2:$F$8921,"FÅR") -> 6 | J9: =COUNTIFS('Requirement Register'!$B$2:$B$8921,$A9,'Requirement Register'!$F$2:$F$8921,"KAN") -> 1 | K9: =COUNTIFS('Requirement Register'!$B$2:$B$8921,$A9,'Requirement Register'!$F$2:$F$8921,"") -> 0
A10: 9 | B10: Privacy-arkitektur och private-by-default-gränser | C10: =COUNTIF('Requirement Register'!$B$2:$B$8921,A10) -> 193 | D10: MI-09-001 | E10: MI-09-193 | F10: =COUNTIFS('Requirement Register'!$B$2:$B$8921,$A10,'Requirement Register'!$F$2:$F$8921,"SKA") -> 117 | G10: =COUNTIFS('Requirement Register'!$B$2:$B$8921,$A10,'Requirement Register'!$F$2:$F$8921,"FÅR INTE") -> 66 | H10: =COUNTIFS('Requirement Register'!$B$2:$B$8921,$A10,'Requirement Register'!$F$2:$F$8921,"BÖR") -> 5 | I10: =COUNTIFS('Requirement Register'!$B$2:$B$8921,$A10,'Requirement Register'!$F$2:$F$8921,"FÅR") -> 5 | J10: =COUNTIFS('Requirement Register'!$B$2:$B$8921,$A10,'Requirement Register'!$F$2:$F$8921,"KAN") -> 0 | K10: =COUNTIFS('Requirement Register'!$B$2:$B$8921,$A10,'Requirement Register'!$F$2:$F$8921,"") -> 0
A11: 10 | B11: Kommunikationskanaler, konton och innehållsåtkomst | C11: =COUNTIF('Requirement Register'!$B$2:$B$8921,A11) -> 213 | D11: MI-10-001 | E11: MI-10-213 | F11: =COUNTIFS('Requirement Register'!$B$2:$B$8921,$A11,'Requirement Register'!$F$2:$F$8921,"SKA") -> 138 | G11: =COUNTIFS('Requirement Register'!$B$2:$B$8921,$A11,'Requirement Register'!$F$2:$F$8921,"FÅR INTE") -> 65 | H11: =COUNTIFS('Requirement Register'!$B$2:$B$8921,$A11,'Requirement Register'!$F$2:$F$8921,"BÖR") -> 6 | I11: =COUNTIFS('Requirement Register'!$B$2:$B$8921,$A11,'Requirement Register'!$F$2:$F$8921,"FÅR") -> 4 | J11: =COUNTIFS('Requirement Register'!$B$2:$B$8921,$A11,'Requirement Register'!$F$2:$F$8921,"KAN") -> 0 | K11: =COUNTIFS('Requirement Register'!$B$2:$B$8921,$A11,'Requirement Register'!$F$2:$F$8921,"") -> 0
A12: 11 | B12: Utgående kommunikation, varumärkesidentitet och mänsklig representation | C12: =COUNTIF('Requirement Register'!$B$2:$B$8921,A12) -> 221 | D12: MI-11-001 | E12: MI-11-221 | F12: =COUNTIFS('Requirement Register'!$B$2:$B$8921,$A12,'Requirement Register'!$F$2:$F$8921,"SKA") -> 138 | G12: =COUNTIFS('Requirement Register'!$B$2:$B$8921,$A12,'Requirement Register'!$F$2:$F$8921,"FÅR INTE") -> 71 | H12: =COUNTIFS('Requirement Register'!$B$2:$B$8921,$A12,'Requirement Register'!$F$2:$F$8921,"BÖR") -> 7 | I12: =COUNTIFS('Requirement Register'!$B$2:$B$8921,$A12,'Requirement Register'!$F$2:$F$8921,"FÅR") -> 5 | J12: =COUNTIFS('Requirement Register'!$B$2:$B$8921,$A12,'Requirement Register'!$F$2:$F$8921,"KAN") -> 0 | K12: =COUNTIFS('Requirement Register'!$B$2:$B$8921,$A12,'Requirement Register'!$F$2:$F$8921,"") -> 0
A13: 12 | B13: Notifieringar, mänsklig uppmärksamhet och prioritetsgovernance | C13: =COUNTIF('Requirement Register'!$B$2:$B$8921,A13) -> 225 | D13: MI-12-001 | E13: MI-12-225 | F13: =COUNTIFS('Requirement Register'!$B$2:$B$8921,$A13,'Requirement Register'!$F$2:$F$8921,"SKA") -> 146 | G13: =COUNTIFS('Requirement Register'!$B$2:$B$8921,$A13,'Requirement Register'!$F$2:$F$8921,"FÅR INTE") -> 58 | H13: =COUNTIFS('Requirement Register'!$B$2:$B$8921,$A13,'Requirement Register'!$F$2:$F$8921,"BÖR") -> 8 | I13: =COUNTIFS('Requirement Register'!$B$2:$B$8921,$A13,'Requirement Register'!$F$2:$F$8921,"FÅR") -> 13 | J13: =COUNTIFS('Requirement Register'!$B$2:$B$8921,$A13,'Requirement Register'!$F$2:$F$8921,"KAN") -> 0 | K13: =COUNTIFS('Requirement Register'!$B$2:$B$8921,$A13,'Requirement Register'!$F$2:$F$8921,"") -> 0
... A33: 32 | B33: Mobilupplevelse, daglig drift och canonical implementation contract | C33: =COUNTIF('Requirement Register'!$B$2:$B$8921,A33) -> 350 | D33: MI-32-001 | E33: MI-32-350 | F33: =COUNTIFS('Requirement Register'!$B$2:$B$8921,$A33,'Requirement Register'!$F$2:$F$8921,"SKA") -> 253 | G33: =COUNTIFS('Requirement Register'!$B$2:$B$8921,$A33,'Requirement Register'!$F$2:$F$8921,"FÅR INTE") -> 91 | H33: =COUNTIFS('Requirement Register'!$B$2:$B$8921,$A33,'Requirement Register'!$F$2:$F$8921,"BÖR") -> 2 | I33: =COUNTIFS('Requirement Register'!$B$2:$B$8921,$A33,'Requirement Register'!$F$2:$F$8921,"FÅR") -> 4 | J33: =COUNTIFS('Requirement Register'!$B$2:$B$8921,$A33,'Requirement Register'!$F$2:$F$8921,"KAN") -> 0 | K33: =COUNTIFS('Requirement Register'!$B$2:$B$8921,$A33,'Requirement Register'!$F$2:$F$8921,"") -> 0
B34: Totalt | C34: =SUM(C2:C33) -> 8920 | F34: =SUM(F2:F33) -> 5886 | G34: =SUM(G2:G33) -> 2602 | H34: =SUM(H2:H33) -> 210 | I34: =SUM(I2:I33) -> 207 | J34: =SUM(J2:J33) -> 6 | K34: =SUM(K2:K33) -> 9

Sheet Läsanvisning
A1: Omnira — Mobile Intelligence & Device Control — Requirement Register
A2: Status | B2: Canonical Edition v1.0 — APPROVED
A4: Utgåva | B4: r2 — efter normativ terminologistandardisering
A5: Innehåll | B5: Samtliga 8 920 normativa kontrakt ur Kapitel 1–32.
A6: Källa | B6: Sources/Canonical-Source-Set-v1.0/ — canonical source-set med 22 tillämpade terminologikorrigeringar.
A7: Ändring mot r1 | B7: 22 krav standardiserade till FÅR INTE. Ingen annan textändring. FÅR INTE: 2 580 → 2 602. SKA INTE: 2 → 0. ÄR FÖRBJUDEN/-ET/-NA: 20 → 0.
A8: Extraktionsmetod | B8: Fristående stycke som exakt matchar MI-KK-NNN är ett kontrakt-ID. Kravtexten är omedelbart följande stycke, ordagrant.
A9: Normativ term | B9: Första term ur Chapter Plan §7-vokabulären, prioritet FÅR INTE, SKA INTE, SKA, FÅR, BÖR, KAN.
A10: Utan term | B10: 9 krav (var 29) saknar §7-term. Samtliga är beskrivande eller uppräknande satser där normativ term inte är avsedd.
A11: Verifiering | B11: 8 920 ID, inga dubbletter, inga luckor, samtliga har kravtext, noll kvarvarande SKA INTE eller ÄR FÖRBJUDEN.
A13: Godkännandestatus | B13: APPROVED
A14: Godkänd av | B14: André Hultgren
A15: Godkännandedatum | B15: 2026-07-30
... A17: Ändring mot r2 | B17: Endast status- och paketmetadata. Ingen kravtext, inget ID och ingen tolkning har ändrats.
